<?xml version="1.0" ?>
<robot name="mecanum_wheeled_robot" >
  <!-- Wheels -->
  <!-- in kg-->
  <!-- Defining the colors used in this robot -->
  <material name="Black">
    <color rgba="0.0 0.0 0.0 1.0"/>
  </material>
  <material name="Red">
    <color rgba="0.8 0.0 0.0 1.0"/>
  </material>
  <material name="White">
    <color rgba="1.0 1.0 1.0 1.0"/>
  </material>
  <material name="Blue">
    <color rgba="0.0 0.0 0.8 1.0"/>
  </material>
  <material name="base">
   <texture filename="package://thedush_robots/texture/texture5.jpg"/>
  </material>
   <material name="Wheels1">
   <texture filename="package://thedush_robots/texture/texture2.png"/>
  </material>
  <!-- PROPERTY LIST -->
  <!--All units in m-kg-s-radians unit system -->
  <!-- Main body radius and height -->
  <!-- Main Body Cylinder base   -->
  <!-- in kg-->
  <!-- caster wheel radius and height -->
  <!-- caster wheel mass -->
  <!-- in kg-->
  <!-- caster wheel radius and height -->
  <!-- caster wheel mass -->
  <!-- in kg-->
  <!-- Wheels -->
 
 
  <!-- in kg-->
  <!-- Hokuyo Laser scanner -->
  <!-- Macro for calculating inertia of cylinder -->
  <!-- BASE-FOOTPRINT -->
  <!-- base_footprint is a fictitious link(frame) that is on the ground right below base_link origin -->
  <link name="base_footprint">
    <inertial>
      <mass value="0.0001"/>
      <origin xyz="0 0 0"/>
      <inertia ixx="0.0001" ixy="0.0" ixz="0.0" iyy="0.0001" iyz="0.0" izz="0.0001"/>
    </inertial>
    <visual>
      <origin rpy="1.57 1.57 1.57" xyz="0 0 0"/>
      <geometry>
        <box size="0.001 0.001 0.001"/>
      </geometry>
    </visual>
  </link>
  <gazebo reference="base_footprint">
    <turnGravityOff>false</turnGravityOff>
  </gazebo>
  <joint name="base_footprint_joint" type="fixed">
    <origin rpy="0 0 0" xyz="0 0 0.04"/>
    <parent link="base_footprint"/>
    <child link="base_link"/>
  </joint>
  <!-- BASE-LINK -->
  <!--Actual body/chassis of the robot-->
  <link name="base_link">
    <inertial>
      <mass value="5"/>
      <origin xyz="0 0 0"/>
      <!--The 3x3 rotational inertia matrix. -->
      <inertia ixx="0.0282916666667" ixy="0" ixz="0" iyy="0.0282916666667" iyz="0" izz="0.05625"/>
    </inertial>
    <visual>
      <origin rpy="1.57079632679 0 0" xyz="0 0 0.03"/>
      <geometry>
       <mesh
          filename="package://thedush_robots/meshes/robot_case/mecanum_case.STL" />
      </geometry>
      <material name="base"/>
    </visual>
    <collision>
      <origin rpy="1.57079632679 0 0 " xyz="0 0 0.04"/>
      <geometry>
        <mesh
          filename="package://thedush_robots/meshes/robot_case/mecanum_case.STL" />
      </geometry>
    </collision>
  </link>
  <gazebo reference="base_link">
    <material>Gazebo/White</material>
    <turnGravityOff>false</turnGravityOff>
  </gazebo>
  <!--fb : front, back ; lr: left, right -->
  <link name="front_right_wheel">
    <visual>
      <origin rpy="1.57079632679 0  1.57079632679 " xyz="0 0 0"/>
      <geometry>
        <mesh
          filename="package://thedush_robots/meshes/wheels/mecanumwheel.STL" />
      </geometry>
      <material name="Wheels1"/>
    </visual>
    <collision>
      <origin rpy="1.57079632679 0 1.57079632679 " xyz="0 0 0"/>
      <geometry>
        <mesh
          filename="package://thedush_robots/meshes/wheels/mecanumwheel.STL"/>
      </geometry>
    </collision>
    <inertial>
      <mass value="2.5"/>
      <origin xyz="0 0 0"/>
      <inertia ixx="0.00108333333333" ixy="0" ixz="0" iyy="0.00108333333333" iyz="0" izz="0.002"/>
    </inertial>
  </link>



   <link name="back_right_wheel">
    <visual>
      <origin rpy="1.57079632679 0  1.57079632679 " xyz="0 0 0"/>
      <geometry>
        <mesh
          filename="package://thedush_robots/meshes/wheels/mecanumwheel.STL"/>
      </geometry>
      <material name="Wheels1"/>
    </visual>
    <collision>
      <origin rpy="1.57079632679 0 1.57079632679 " xyz="0 0 0"/>
      <geometry>
        <mesh
          filename="package://thedush_robots/meshes/wheels/mecanumwheel.STL" />
      </geometry>
    </collision>
    <inertial>
      <mass value="2.5"/>
      <origin xyz="0 0 0"/>
      <inertia ixx="0.00108333333333" ixy="0" ixz="0" iyy="0.00108333333333" iyz="0" izz="0.002"/>
    </inertial>
  </link>



  <gazebo reference="front_right_wheel">
    <mu1 value="1.0"/>
    <mu2 value="1.0"/>
    <kp value="10000000.0"/>
    <kd value="1.0"/>
    <fdir1 value="1 0 0"/>
    <material>Gazebo/Grey</material>
    <turnGravityOff>false</turnGravityOff>
  </gazebo>

 <gazebo reference="back_right_wheel">
    <mu1 value="1.0"/>
    <mu2 value="1.0"/>
    <kp value="10000000.0"/>
    <kd value="1.0"/>
    <fdir1 value="1 0 0"/>
    <material>Gazebo/Grey</material>
    <turnGravityOff>false</turnGravityOff>
  </gazebo>

  <joint name="front_right_wheel_joint" type="continuous">
    <parent link="base_link"/>
    <child link="front_right_wheel"/>
    <origin rpy="0 0 0" xyz="-0.18381026754975 0.00933097076 0.01"/>
    <axis rpy="0 0" xyz="1 0 0">
    </axis>
    <limit effort="100" velocity="100"/>
    <joint_properties damping="0.0" friction="0.0"/>
  </joint>


  <joint name="back_right_wheel_joint" type="continuous">
    <parent link="base_link"/>
    <child link="back_right_wheel"/>
    <origin rpy="0 0 0" xyz="-0.18381026754975 -0.308708338737 0.01"/>
    <axis rpy="0  0" xyz="1 0 0"/>
    <limit effort="100" velocity="100"/>
    <joint_properties damping="0.0" friction="0.0"/>
  </joint>

  <!-- Transmission is important to link the joints and the controller -->
  <transmission name="front_right_wheel_joint_trans">
    <type>transmission_interface/SimpleTransmission</type>
    <joint name="front_right_wheel_joint"/>
    <actuator name="front_right_wheel_joint_motor">
      <hardwareInterface>EffortJointInterface</hardwareInterface>
      <mechanicalReduction>1</mechanicalReduction>
    </actuator>
  </transmission>

 <transmission name="back_right_wheel_joint_trans">
    <type>transmission_interface/SimpleTransmission</type>
    <joint name="back_right_wheel_joint"/>
    <actuator name="back_right_wheel_joint_motor">
      <hardwareInterface>EffortJointInterface</hardwareInterface>
      <mechanicalReduction>1</mechanicalReduction>
    </actuator>
  </transmission>


  <!--fb : front, back ; lr: left, right -->
  <link name="front_left_wheel">
    <visual>
      <origin rpy="1.57079632679 0  -1.57079632679 " xyz="0 0 0"/>
      <geometry>
        <mesh
          filename="package://thedush_robots/meshes/wheels/mecanumwheel.STL" />
      </geometry>
      <material name="Wheels1"/>
    </visual>
    <collision>
      <origin rpy="1.57079632679 0 -1.57079632679 " xyz="0 0 0"/>
      <geometry>
        <mesh
          filename="package://thedush_robots/meshes/wheels/mecanumwheel.STL"/>
      </geometry>
    </collision>
    <inertial>
      <mass value="2.5"/>
      <origin xyz="0 0 0"/>
      <inertia ixx="0.00108333333333" ixy="0" ixz="0" iyy="0.00108333333333" iyz="0" izz="0.002"/>
    </inertial>
  </link>

   <link name="back_left_wheel">
    <visual>
      <origin rpy="1.57079632679 0  -1.57079632679 " xyz="0 0 0"/>
      <geometry>
        <mesh
          filename="package://thedush_robots/meshes/wheels/mecanumwheel.STL" />
      </geometry>
      <material name="Wheels1"/>
    </visual>
    <collision>
      <origin rpy="1.57079632679 0 -1.57079632679 " xyz="0 0 0"/>
      <geometry>
        <mesh
          filename="package://thedush_robots/meshes/wheels/mecanumwheel.STL" />
      </geometry>
    </collision>
    <inertial>
      <mass value="2.5"/>
      <origin xyz="0 0 0"/>
      <inertia ixx="0.00108333333333" ixy="0" ixz="0" iyy="0.00108333333333" iyz="0" izz="0.002"/>
    </inertial>
  </link>


  <gazebo reference="front_left_wheel">
    <mu1 value="1.0"/>
    <mu2 value="1.0"/>
    <kp value="10000000.0"/>
    <kd value="1.0"/>
    <fdir1 value="1 0 0"/>
    <material>Gazebo/Grey</material>
    <turnGravityOff>false</turnGravityOff>
  </gazebo>

  <gazebo reference="back_left_wheel">
    <mu1 value="1.0"/>
    <mu2 value="1.0"/>
    <kp value="10000000.0"/>
    <kd value="1.0"/>
    <fdir1 value="1 0 0"/>
    <material>Gazebo/Grey</material>
    <turnGravityOff>false</turnGravityOff>
  </gazebo>


  <joint name="front_left_wheel_joint" type="continuous">
    <parent link="base_link"/>
    <child link="front_left_wheel"/>
    <origin rpy="0 0 0" xyz="0.35695439024 -0.00833097076 0.01"/>
    <axis rpy="0  0" xyz="1 0 0"/>
    <limit effort="100" velocity="100"/>
    <joint_properties damping="0.0" friction="0.0"/>
  </joint>



  <joint name="back_left_wheel_joint" type="continuous">
    <parent link="base_link"/>
    <child link="back_left_wheel"/>
    <origin rpy="0 0 0" xyz="0.3565439024 -0.325708338737 0.01"/>
    <axis rpy="0  0" xyz="1 0 0"/>
    <limit effort="100" velocity="100"/>
    <joint_properties damping="0.0" friction="0.0"/>
  </joint>

  <!-- Transmission is important to link the joints and the controller -->
  <transmission name="front_left_wheel_joint_trans">
    <type>transmission_interface/SimpleTransmission</type>
    <joint name="front_left_wheel_joint"/>
    <actuator name="front_left_wheel_joint_motor">
      <hardwareInterface>EffortJointInterface</hardwareInterface>
      <mechanicalReduction>1</mechanicalReduction>
    </actuator>
  </transmission>



    <transmission name="back_left_wheel_joint_trans">
    <type>transmission_interface/SimpleTransmission</type>
    <joint name="back_left_wheel_joint"/>
    <actuator name="back_left_wheel_joint_motor">
      <hardwareInterface>EffortJointInterface</hardwareInterface>
      <mechanicalReduction>1</mechanicalReduction>
    </actuator>
  </transmission>

  
 


 
  <link name="hokuyo_link">
    <visual>
      <origin rpy="0 0 1.57079632679" xyz="0 0 0"/>
      <geometry>
        <mesh
          filename="package://thedush_robots/meshes/sensors/xtion_pro_live.dae"/>
    
       <!--  <box size="0.05 0.05 0.05"/> -->
      </geometry>
      <material name="Blue"/>
    </visual>
  </link>
  <joint name="hokuyo_joint" type="fixed">
    <origin rpy="0 0 0" xyz="0.0926225844026 0.0192884281278 0.129905364513"/>
    <parent link="base_link"/>
    <child link="hokuyo_link"/>
  </joint>
  <gazebo reference="hokuyo_link">
    <material>Gazebo/Grey</material>
    <turnGravityOff>false</turnGravityOff>
    <sensor name="head_hokuyo_sensor" type="ray">
      <pose>0.025 0 0 0 0 0</pose>
      <visualize>false</visualize>
      <update_rate>40</update_rate>
      <ray>
        <scan>
          <horizontal>
            <samples>720</samples>
            <resolution>1</resolution>
            <min_angle>-1.570796</min_angle>
            <max_angle>1.570796</max_angle>
          </horizontal>
        </scan>
        <range>
          <min>0.10</min>
          <max>10.0</max>
          <resolution>0.001</resolution>
        </range>
      </ray>
      <plugin filename="libgazebo_ros_laser.so" name="gazebo_ros_head_hokuyo_controller">
        <topicName>/scan</topicName>
        <frameName>hokuyo_link</frameName>
      </plugin>
    </sensor>
  </gazebo>



  <gazebo>
    <plugin name="object_controller" filename="libgazebo_ros_planar_move.so">
      <commandTopic>cmd_vel</commandTopic>
      <odometryTopic>odom</odometryTopic>
      <odometryFrame>odom</odometryFrame>
      <odometryRate>20.0</odometryRate>
      <robotBaseFrame>base_footprint</robotBaseFrame>
    </plugin>
  </gazebo>
  <!--
	  <gazebo>
	    <plugin name="kobuki_controller" filename="libgazebo_ros_kobuki.so">
	      <publish_tf>1</publish_tf>
	      <left_wheel_joint_name>front_left_wheel_joint</left_wheel_joint_name>
	      <right_wheel_joint_name>front_right_wheel_joint</right_wheel_joint_name>
	      <wheel_separation>.30</wheel_separation>
	      <wheel_diameter>0.08</wheel_diameter>
	      <torque>30.0</torque>
	      <velocity_command_timeout>0.6</velocity_command_timeout>


	    </plugin>
	  </gazebo>

-->
  <!--
<gazebo>
    <plugin name="gazebo_ros_control" filename="libgazebo_ros_control.so" />
    <plugin filename="libgazebo_ros_joint_state_publisher.so" name="joint_state_publisher">
      <jointName>front_right_wheel_joint, front_left_wheel_joint</jointName>
      <updateRate>10.0</updateRate>
      <alwaysOn>true</alwaysOn>
    </plugin>
</gazebo>
-->
</robot>

